2019-03-28 10:25:10,275 ERROR: Exception on /edit_profile [POST] [in /home/jurgeon/.local/lib/python3.6/site-packages/flask/app.py:1761]
Traceback (most recent call last):
  File "/home/jurgeon/.local/lib/python3.6/site-packages/flask/app.py", line 2292, in wsgi_app
    response = self.full_dispatch_request()
  File "/home/jurgeon/.local/lib/python3.6/site-packages/flask/app.py", line 1815, in full_dispatch_request
    rv = self.handle_user_exception(e)
  File "/home/jurgeon/.local/lib/python3.6/site-packages/flask/app.py", line 1718, in handle_user_exception
    reraise(exc_type, exc_value, tb)
  File "/home/jurgeon/.local/lib/python3.6/site-packages/flask/_compat.py", line 35, in reraise
    raise value
  File "/home/jurgeon/.local/lib/python3.6/site-packages/flask/app.py", line 1813, in full_dispatch_request
    rv = self.dispatch_request()
  File "/home/jurgeon/.local/lib/python3.6/site-packages/flask/app.py", line 1799, in dispatch_request
    return self.view_functions[rule.endpoint](**req.view_args)
  File "/home/jurgeon/.local/lib/python3.6/site-packages/flask_login/utils.py", line 261, in decorated_view
    return func(*args, **kwargs)
  File "/home/jurgeon/Dropbox/dev/flask_projects/microblog/app/routes.py", line 146, in edit_profile
    if form.validate_on_submit():
  File "/home/jurgeon/.local/lib/python3.6/site-packages/flask_wtf/form.py", line 101, in validate_on_submit
    return self.is_submitted() and self.validate()
  File "/home/jurgeon/.local/lib/python3.6/site-packages/wtforms/form.py", line 310, in validate
    return super(Form, self).validate(extra)
  File "/home/jurgeon/.local/lib/python3.6/site-packages/wtforms/form.py", line 152, in validate
    if not field.validate(self, extra):
  File "/home/jurgeon/.local/lib/python3.6/site-packages/wtforms/fields/core.py", line 206, in validate
    stop_validation = self._run_validation_chain(form, chain)
  File "/home/jurgeon/.local/lib/python3.6/site-packages/wtforms/fields/core.py", line 226, in _run_validation_chain
    validator(form, self)
  File "/home/jurgeon/Dropbox/dev/flask_projects/microblog/app/forms.py", line 56, in validate_username
    if username.data != self.original_username:
NameError: name 'current_user' is not defined
2019-03-28 10:25:11,228 ERROR: Exception on /edit_profile [POST] [in /home/jurgeon/.local/lib/python3.6/site-packages/flask/app.py:1761]
Traceback (most recent call last):
  File "/home/jurgeon/.local/lib/python3.6/site-packages/flask/app.py", line 2292, in wsgi_app
    response = self.full_dispatch_request()
  File "/home/jurgeon/.local/lib/python3.6/site-packages/flask/app.py", line 1815, in full_dispatch_request
    rv = self.handle_user_exception(e)
  File "/home/jurgeon/.local/lib/python3.6/site-packages/flask/app.py", line 1718, in handle_user_exception
    reraise(exc_type, exc_value, tb)
  File "/home/jurgeon/.local/lib/python3.6/site-packages/flask/_compat.py", line 35, in reraise
    raise value
  File "/home/jurgeon/.local/lib/python3.6/site-packages/flask/app.py", line 1813, in full_dispatch_request
    rv = self.dispatch_request()
  File "/home/jurgeon/.local/lib/python3.6/site-packages/flask/app.py", line 1799, in dispatch_request
    return self.view_functions[rule.endpoint](**req.view_args)
  File "/home/jurgeon/.local/lib/python3.6/site-packages/flask_login/utils.py", line 261, in decorated_view
    return func(*args, **kwargs)
  File "/home/jurgeon/Dropbox/dev/flask_projects/microblog/app/routes.py", line 146, in edit_profile
    if form.validate_on_submit():
  File "/home/jurgeon/.local/lib/python3.6/site-packages/flask_wtf/form.py", line 101, in validate_on_submit
    return self.is_submitted() and self.validate()
  File "/home/jurgeon/.local/lib/python3.6/site-packages/wtforms/form.py", line 310, in validate
    return super(Form, self).validate(extra)
  File "/home/jurgeon/.local/lib/python3.6/site-packages/wtforms/form.py", line 152, in validate
    if not field.validate(self, extra):
  File "/home/jurgeon/.local/lib/python3.6/site-packages/wtforms/fields/core.py", line 206, in validate
    stop_validation = self._run_validation_chain(form, chain)
  File "/home/jurgeon/.local/lib/python3.6/site-packages/wtforms/fields/core.py", line 226, in _run_validation_chain
    validator(form, self)
  File "/home/jurgeon/Dropbox/dev/flask_projects/microblog/app/forms.py", line 56, in validate_username
    if username.data != self.original_username:
NameError: name 'current_user' is not defined
2019-03-28 10:25:26,995 INFO: Microblog startup [in /home/jurgeon/Dropbox/dev/flask_projects/microblog/app/__init__.py:50]
2019-03-28 10:25:41,946 INFO: Microblog startup [in /home/jurgeon/Dropbox/dev/flask_projects/microblog/app/__init__.py:50]
2019-03-28 10:27:39,590 INFO: Microblog startup [in /home/jurgeon/Dropbox/dev/flask_projects/microblog/app/__init__.py:50]
2019-03-28 10:48:49,231 INFO: Microblog startup [in /home/jurgeon/Dropbox/dev/flask_projects/microblog/app/__init__.py:50]
2019-03-28 11:05:17,241 INFO: Microblog startup [in /home/jurgeon/Dropbox/dev/flask_projects/microblog/app/__init__.py:50]
2019-03-28 12:10:01,853 INFO: Microblog startup [in /home/jurgeon/Dropbox/dev/flask_projects/microblog/app/__init__.py:50]
2019-03-28 12:37:52,817 INFO: Microblog startup [in /home/jurgeon/Dropbox/dev/flask_projects/microblog/app/__init__.py:50]
2019-03-28 12:41:35,375 INFO: Microblog startup [in /home/jurgeon/Dropbox/dev/flask_projects/microblog/app/__init__.py:50]
2019-03-28 12:42:07,732 INFO: Microblog startup [in /home/jurgeon/Dropbox/dev/flask_projects/microblog/app/__init__.py:50]
2019-03-28 12:43:05,904 INFO: Microblog startup [in /home/jurgeon/Dropbox/dev/flask_projects/microblog/app/__init__.py:50]
2019-03-28 12:43:33,574 INFO: Microblog startup [in /home/jurgeon/Dropbox/dev/flask_projects/microblog/app/__init__.py:50]
2019-03-28 12:43:39,780 ERROR: Exception on /index [GET] [in /home/jurgeon/.local/lib/python3.6/site-packages/flask/app.py:1761]
Traceback (most recent call last):
  File "/home/jurgeon/.local/lib/python3.6/site-packages/flask/app.py", line 2292, in wsgi_app
    response = self.full_dispatch_request()
  File "/home/jurgeon/.local/lib/python3.6/site-packages/flask/app.py", line 1815, in full_dispatch_request
    rv = self.handle_user_exception(e)
  File "/home/jurgeon/.local/lib/python3.6/site-packages/flask/app.py", line 1718, in handle_user_exception
    reraise(exc_type, exc_value, tb)
  File "/home/jurgeon/.local/lib/python3.6/site-packages/flask/_compat.py", line 35, in reraise
    raise value
  File "/home/jurgeon/.local/lib/python3.6/site-packages/flask/app.py", line 1813, in full_dispatch_request
    rv = self.dispatch_request()
  File "/home/jurgeon/.local/lib/python3.6/site-packages/flask/app.py", line 1799, in dispatch_request
    return self.view_functions[rule.endpoint](**req.view_args)
  File "/home/jurgeon/.local/lib/python3.6/site-packages/flask_login/utils.py", line 261, in decorated_view
    return func(*args, **kwargs)
  File "/home/jurgeon/Dropbox/dev/flask_projects/microblog/app/main/routes.py", line 35, in index
    page, app.config['POSTS_PER_PAGE'], False)
NameError: name 'app' is not defined
2019-03-28 12:43:41,351 ERROR: Exception on /index [GET] [in /home/jurgeon/.local/lib/python3.6/site-packages/flask/app.py:1761]
Traceback (most recent call last):
  File "/home/jurgeon/.local/lib/python3.6/site-packages/flask/app.py", line 2292, in wsgi_app
    response = self.full_dispatch_request()
  File "/home/jurgeon/.local/lib/python3.6/site-packages/flask/app.py", line 1815, in full_dispatch_request
    rv = self.handle_user_exception(e)
  File "/home/jurgeon/.local/lib/python3.6/site-packages/flask/app.py", line 1718, in handle_user_exception
    reraise(exc_type, exc_value, tb)
  File "/home/jurgeon/.local/lib/python3.6/site-packages/flask/_compat.py", line 35, in reraise
    raise value
  File "/home/jurgeon/.local/lib/python3.6/site-packages/flask/app.py", line 1813, in full_dispatch_request
    rv = self.dispatch_request()
  File "/home/jurgeon/.local/lib/python3.6/site-packages/flask/app.py", line 1799, in dispatch_request
    return self.view_functions[rule.endpoint](**req.view_args)
  File "/home/jurgeon/.local/lib/python3.6/site-packages/flask_login/utils.py", line 261, in decorated_view
    return func(*args, **kwargs)
  File "/home/jurgeon/Dropbox/dev/flask_projects/microblog/app/main/routes.py", line 35, in index
    page, app.config['POSTS_PER_PAGE'], False)
NameError: name 'app' is not defined
2019-03-28 12:44:55,955 INFO: Microblog startup [in /home/jurgeon/Dropbox/dev/flask_projects/microblog/app/__init__.py:50]
2019-03-28 12:44:57,745 ERROR: Exception on /index [GET] [in /home/jurgeon/.local/lib/python3.6/site-packages/flask/app.py:1761]
Traceback (most recent call last):
  File "/home/jurgeon/.local/lib/python3.6/site-packages/flask/app.py", line 2292, in wsgi_app
    response = self.full_dispatch_request()
  File "/home/jurgeon/.local/lib/python3.6/site-packages/flask/app.py", line 1815, in full_dispatch_request
    rv = self.handle_user_exception(e)
  File "/home/jurgeon/.local/lib/python3.6/site-packages/flask/app.py", line 1718, in handle_user_exception
    reraise(exc_type, exc_value, tb)
  File "/home/jurgeon/.local/lib/python3.6/site-packages/flask/_compat.py", line 35, in reraise
    raise value
  File "/home/jurgeon/.local/lib/python3.6/site-packages/flask/app.py", line 1813, in full_dispatch_request
    rv = self.dispatch_request()
  File "/home/jurgeon/.local/lib/python3.6/site-packages/flask/app.py", line 1799, in dispatch_request
    return self.view_functions[rule.endpoint](**req.view_args)
  File "/home/jurgeon/.local/lib/python3.6/site-packages/flask_login/utils.py", line 261, in decorated_view
    return func(*args, **kwargs)
  File "/home/jurgeon/Dropbox/dev/flask_projects/microblog/app/main/routes.py", line 35, in index
    page, app.config['POSTS_PER_PAGE'], False)
NameError: name 'app' is not defined
2019-03-28 12:45:43,842 INFO: Microblog startup [in /home/jurgeon/Dropbox/dev/flask_projects/microblog/app/__init__.py:50]
